Workbook

Sheet FactuScore (2)
A1: Facturación por Score (S/MM) | AM1: PRIMA | AN1: 12.704389 | AO1: 12.641761 | AP1: 12.529264 | AQ1: 12.452429 | AR1: 12.386583 | AS1: 12.291931 | AT1: 12.225291 | AU1: 12.187898 | AV1: 12.095706 | AW1: 12.104614 | AX1: 12.11684 | AY1: 12.113452 | AZ1: 12.119329 | BA1: 12.128399
AN2: 0.43347127 | AO2: 0.42569774 | AP2: 0.42743296 | AQ2: 0.4277685 | AR2: 0.43118991 | AS2: 0.43786192 | AT2: 0.44086771 | AU2: 0.44326811 | AV2: 0.44415135 | AW2: 0.44279495 | AX2: 0.44055663 | AY2: 0.44072213 | AZ2: 0.43817748 | BA2: 0.43386385
A3: ANTERIOR | AM3: CONSUMO | AO3: 0.041959101 | AP3: 0.038380481 | AQ3: 0.037440381 | AR3: 0.037099111 | AS3: 0.039131966 | AT3: 0.039801473 | AU3: 0.039978124 | AV3: 0.038100903 | AW3: 0.038573972 | AX3: 0.038596267 | AY3: 0.038911516 | AZ3: 0.038713609 | BA3: 0.038606916
AM4: Mto Desembolsado (S/MM) | AO4: 0.009813428 | AP4: 0.0094731906 | AQ4: 0.0085771272 | AR4: 0.0080991818 | AS4: 0.0072980043 | AT4: 0.0065455917 | AU4: 0.0063050191 | AV4: 0.005541759 | AW4: 0.0054600621 | AX4: 0.0053969281 | AY4: 0.0053617356 | AZ4: 0.0052988301 | BA4: 0.0051806663
AS5: Plan Yellow
A6: Facturación | B6: 202101 | C6: 202102 | D6: 202103 | E6: 202104 | F6: 202105 | G6: 202106 | H6: 202107-Proy | I6: Jun - May | AS6: 202101 | AT6: 202102 | AU6: 202103
A7: MUY ALTO | B7: 256.59138 | C7: 217.4677 | D7: 317.36218 | E7: 294.6018 | F7: 346.1021 | G7: 314.83821 | H7: =+H$13*(#REF!/#REF!) -> #REF! | I7: =G7-F7 -> -31.263891 | AS7: 256.59138 | AT7: 217.4677 | AU7: 295.04113
A8: ALTO | B8: 128.30226 | C8: 119.71832 | D8: 177.25392 | E8: 165.10622 | F8: 174.62132 | G8: 158.85011 | H8: =+H$13*(#REF!/#REF!) -> #REF! | I8: =G8-F8 -> -15.771208 | AS8: 128.30226 | AT8: 119.71832 | AU8: 146.97315
A9: MEDIO | B9: 64.892364 | C9: 59.756773 | D9: 86.713302 | E9: 81.92946 | F9: 85.355396 | G9: 83.628558 | H9: =+H$13*(#REF!/#REF!) -> #REF! | I9: =G9-F9 -> -1.726838 | AS9: 64.892364 | AT9: 59.756773 | AU9: 75.779706
A10: BAJO | B10: 97.969837 | C10: 92.706152 | D10: 128.28817 | E10: 121.28794 | F10: 135.66866 | G10: 138.66339 | H10: =+H$13*(#REF!/#REF!) -> #REF! | I10: =G10-F10 -> 2.9947286 | AS10: 97.969837 | AT10: 92.706152 | AU10: 115.03886
A11: MUY BAJO | B11: 36.105297 | C11: 36.376225 | D11: 48.339105 | E11: 43.697523 | F11: 50.39221 | G11: 56.175929 | H11: =+H$13*(#REF!/#REF!) -> #REF! | I11: =G11-F11 -> 5.7837193 | AS11: 36.105297 | AT11: 36.376225 | AU11: 43.332879
A12: RECHAZO | B12: 9.8998813 | C12: 10.061747 | D12: 12.516528 | E12: 9.7740536 | F12: 11.120408 | G12: 11.091556 | H12: =+H$13*(#REF!/#REF!) -> #REF! | I12: =G12-F12 -> -0.028852226 | AS12: 9.8998813 | AT12: 10.067113 | AU12: 13.834277
A13: Total | B13: =+SUM(B7:B12) -> 593.76102 | C13: =+SUM(C7:C12) -> 536.08691 | D13: =+SUM(D7:D12) -> 770.4732 | E13: 716.397 | F13: 815.0871 | G13: 776.05889 | H13: 845.97688 | I13: =G13-F13 -> -39.028209 | AS13: =+SUM(AS7:AS12) -> 593.76102 | AT13: =+SUM(AT7:AT12) -> 536.09228 | AU13: =+SUM(AU7:AU12) -> 690
A16: Pesos | B16: 202101 | C16: 202102 | D16: 202103 | E16: 202104 | F16: 202105 | G16: 202106 | H16: 202107-Proy | AS16: 202101 | AT16: 202102 | AU16: 202103
A17: MUY ALTO | B17: =+B7/B$13 -> 0.43214588 | C17: =+C7/C$13 -> 0.40565755 | D17: =+D7/D$13 -> 0.41190553 | E17: 0.41122702 | F17: =+F7/F$13 -> 0.42461977 | G17: =+G7/G$13 -> 0.40568855 | H17: =+H7/H$13 -> #REF! | AS17: =+AS7/AS$13 -> 0.43214588 | AT17: =+AT7/AT$13 -> 0.40565349 | AU17: =+AU7/AU$13 -> 0.42759584
A18: ALTO | B18: =+B8/B$13 -> 0.21608401 | C18: =+C8/C$13 -> 0.22331885 | D18: =+D8/D$13 -> 0.23005852 | E18: 0.23046749 | F18: =+F8/F$13 -> 0.21423639 | G18: =+G8/G$13 -> 0.20468822 | H18: =+H8/H$13 -> #REF! | AS18: =+AS8/AS$13 -> 0.21608401 | AT18: =+AT8/AT$13 -> 0.22331662 | AU18: =+AU8/AU$13 -> 0.21300456
A19: MEDIO | B19: =+B9/B$13 -> 0.10929037 | C19: =+C9/C$13 -> 0.11146844 | D19: =+D9/D$13 -> 0.11254551 | E19: 0.11436321 | F19: =+F9/F$13 -> 0.10471936 | G19: =+G9/G$13 -> 0.10776058 | H19: =+H9/H$13 -> #REF! | AS19: =+AS9/AS$13 -> 0.10929037 | AT19: =+AT9/AT$13 -> 0.11146733 | AU19: =+AU9/AU$13 -> 0.10982566
A20: BAJO | B20: =+B10/B$13 -> 0.16499877 | C20: =+C10/C$13 -> 0.1729312 | D20: =+D10/D$13 -> 0.16650568 | E20: 0.16930269 | F20: =+F10/F$13 -> 0.16644683 | G20: =+G10/G$13 -> 0.17867638 | H20: =+H10/H$13 -> #REF! | AS20: =+AS10/AS$13 -> 0.16499877 | AT20: =+AT10/AT$13 -> 0.17292947 | AU20: =+AU10/AU$13 -> 0.16672298
A21: MUY BAJO | B21: =+B11/B$13 -> 0.060807792 | C21: =+C11/C$13 -> 0.067855088 | D21: =+D11/D$13 -> 0.062739502 | E21: 0.06099624 | F21: =+F11/F$13 -> 0.061824325 | G21: =+G11/G$13 -> 0.072386167 | H21: =+H11/H$13 -> #REF! | AS21: =+AS11/AS$13 -> 0.060807792 | AT21: =+AT11/AT$13 -> 0.067854409 | AU21: =+AU11/AU$13 -> 0.062801274
A22: RECHAZO | B22: =+B12/B$13 -> 0.016673175 | C22: =+C12/C$13 -> 0.018768873 | D22: =+D12/D$13 -> 0.016245247 | E22: 0.013643348 | F22: =+F12/F$13 -> 0.013643215 | G22: =+G12/G$13 -> 0.014292158 | H22: =+H12/H$13 -> #REF! | AS22: =+AS12/AS$13 -> 0.016673175 | AT22: =+AT12/AT$13 -> 0.018778694 | AU22: =+AU12/AU$13 -> 0.020049677
A24: MUY ALTO+ALTO | B24: =+B17+B18 -> 0.64822989 | C24: =+C17+C18 -> 0.6289764 | D24: =+D17+D18 -> 0.64196405 | E24: =+E17+E18 -> 0.64169451 | F24: =+F17+F18 -> 0.63885616 | G24: =+G17+G18 -> 0.61037677 | H24: =+H17+H18 -> #REF! | AS24: =+AS17+AS18 -> 0.64822989 | AT24: =+AT17+AT18 -> 0.6289701 | AU24: =+AU17+AU18 -> 0.6406004
AM25: CONSUMO | AN25: 0.045843633 | AO25: 0.041959101 | AP25: 0.038380481 | AQ25: 0.037440381 | AR25: 0.037099111 | AS25: 0.039131966 | AT25: 0.039801473 | AU25: 0.039978124 | AV25: 0.038100903 | AW25: 0.038573972 | AX25: 0.038596267 | AY25: 0.038911516 | AZ25: 0.038713609 | BA25: 0.038606916
A26: Factu Procesada | AM26: Mto Desembolsado (S/MM) | AN26: 0.0095787131 | AO26: 0.009813428 | AP26: 0.0094731906 | AQ26: 0.0085771272 | AR26: 0.0080991818 | AS26: 0.0072980043 | AT26: 0.0065455917 | AU26: 0.0063050191 | AV26: 0.005541759 | AW26: 0.0054600621 | AX26: 0.0053969281 | AY26: 0.0053617356 | AZ26: 0.0052988301 | BA26: 0.0051806663
B28: 202101 | C28: 202102 | D28: 202103 | E28: 202104 | F28: 202105 | G28: 202106 | H28: 202107 | I28: 202108 | J28: 202109 | K28: 202110 | L28: 202111 | M28: 202112 | N28: 202201 | O28: 202202 | P28: 202203 | Q28: 202004 | R28: 202005 | S28: 202206 | T28: 202207 | U28: 202208 | V28: 202209 | W28: 202210 | X28: 202211 | Y28: 202212 | Z28: 202301 | AA28: 202302 | AB28: 202303 Av | AC28: 202303 Proy | AM28: TRX | AN28: 202211 | AO28: 202212 | AP28: 202301 | AQ28: 202302 | AR28: 202303 | AS28: 202304 | AT28: 202305 | AU28: 202306 | AV28: 202307 | AW28: 202308 | AX28: 202309 | AY28: 202310 | AZ28: 202311 | BA28: 202312
A29: MUY ALTO | B29: 257.11812 | C29: 218.31236 | D29: 306.5895 | E29: 304.75928 | F29: 355.64639 | G29: 352.99305 | H29: 420.09653 | I29: 414.51929 | J29: 437.55442 | K29: 450.58582 | L29: 542.37331 | M29: 551.76712 | N29: 495.2257 | O29: 504.59368 | P29: 585.45418 | Q29: 541.69101 | R29: 607.55044 | S29: 561.50284 | T29: 541.56301 | U29: 676.88539 | V29: 570.70913 | W29: 621.03499 | X29: 617.33303 | Y29: 644.06054 | Z29: =+Z60 -> 397.26262 | AC29: =+$AC$35*(Z29/$Y$35) -> 376.30967 | AM29: MUY ALTO | AN29: 6.2755359e+08 | AO29: 6.5081066e+08 | AP29: 5.9598517e+08 | AQ29: 6.0798585e+08 | AR29: 6.6969555e+08 | AS29: 6.3314237e+08 | AT29: 6.8172059e+08 | AU29: 6.4413377e+08 | AV29: 6.8881266e+08 | AW29: 6.92271e+08 | AX29: 6.5647175e+08 | AY29: 6.9709406e+08 | AZ29: 7.2307837e+08 | BA29: 7.6045668e+08
A30: ALTO | B30: 128.76692 | C30: 119.77027 | D30: 179.51381 | E30: 161.99113 | F30: 179.53743 | G30: 170.43719 | H30: 209.70944 | I30: 215.13464 | J30: 214.4942 | K30: 221.13981 | L30: 272.90378 | M30: 281.17183 | N30: 255.1388 | O30: 252.5513 | P30: 296.53019 | Q30: 263.53671 | R30: 296.27304 | S30: 281.93083 | T30: 271.05906 | U30: 351.70207 | V30: 303.44104 | W30: 331.2232 | X30: 336.4268 | Y30: 350.99244 | Z30: =+Z57 -> 262.23898 | AC30: =+$AC$35*(Z30/$Y$35) -> 248.40763 | AM30: ALTO | AN30: 3.5864836e+08 | AO30: 3.895421e+08 | AP30: 3.5776337e+08 | AQ30: 3.62824e+08 | AR30: 3.9519204e+08 | AS30: 3.6807705e+08 | AT30: 3.9458192e+08 | AU30: 3.6938394e+08 | AV30: 3.9255238e+08 | AW30: 3.958199e+08 | AX30: 3.7665789e+08 | AY30: 3.9990339e+08 | AZ30: 4.1977541e+08 | BA30: 4.5002862e+08
A31: MEDIO | B31: 65.110978 | C31: 59.483426 | D31: 89.717292 | E31: 76.486415 | F31: 87.381582 | G31: 82.270583 | H31: 96.660888 | I31: 103.52093 | J31: 99.196516 | K31: 104.46973 | L31: 126.71351 | M31: 130.59912 | N31: 126.35603 | O31: 129.42605 | P31: 149.35837 | Q31: 129.0711 | R31: 150.65258 | S31: 141.22135 | T31: 135.66445 | U31: 171.79711 | V31: 150.48327 | W31: 164.6418 | X31: 166.96185 | Y31: 174.19049 | Z31: =+Z59 -> 140.77577 | AC31: =+$AC$35*(Z31/$Y$35) -> 133.35079 | AM31: MEDIO | AN31: 1.6468708e+08 | AO31: 1.8614339e+08 | AP31: 1.6955178e+08 | AQ31: 1.7677536e+08 | AR31: 1.9499582e+08 | AS31: 1.782129e+08 | AT31: 1.8986801e+08 | AU31: 1.8170857e+08 | AV31: 1.9713108e+08 | AW31: 2.0181652e+08 | AX31: 1.9722807e+08 | AY31: 2.10513e+08 | AZ31: 2.2109495e+08 | BA31: 2.3974194e+08
A32: BAJO | B32: 98.598311 | C32: 91.399719 | D32: 131.65943 | E32: 116.97523 | F32: 127.61457 | G32: 117.20631 | H32: 132.91553 | I32: 147.08075 | J32: 133.26239 | K32: 142.09797 | L32: 174.69552 | M32: 179.17834 | N32: 168.78928 | O32: 171.62193 | P32: 201.95276 | Q32: 173.2128 | R32: 201.31582 | S32: 194.18984 | T32: 186.17407 | U32: 238.65555 | V32: 208.62821 | W32: 222.09163 | X32: 229.75868 | Y32: 239.70611 | Z32: =+Z58 -> 103.69091 | AC32: =+$AC$35*(Z32/$Y$35) -> 98.221903 | AM32: BAJO | AN32: 2.1661358e+08 | AO32: 2.2316281e+08 | AP32: 2.0431157e+08 | AQ32: 2.0830673e+08 | AR32: 2.2305124e+08 | AS32: 1.9941694e+08 | AT32: 2.0847784e+08 | AU32: 1.906646e+08 | AV32: 2.0467184e+08 | AW32: 2.0466137e+08 | AX32: 1.9418437e+08 | AY32: 2.0417095e+08 | AZ32: 2.1361735e+08 | BA32: 2.2577807e+08
A33: MUY BAJO | B33: 36.262 | C33: 36.13715 | D33: 50.419139 | E33: 44.437661 | F33: 49.529513 | G33: 41.368257 | H33: 45.159665 | I33: 52.95658 | J33: 42.645179 | K33: 44.639406 | L33: 56.299005 | M33: 52.065923 | N33: 50.036829 | O33: 53.269351 | P33: 63.242932 | Q33: 53.61645 | R33: 64.397725 | S33: 61.298051 | T33: 58.749585 | U33: 75.195287 | V33: 65.006428 | W33: 68.425065 | X33: 70.917681 | Y33: 73.988071 | Z33: =+Z61 -> 61.335084 | AC33: =+$AC$35*(Z33/$Y$35) -> 58.100068 | AM33: MUY BAJO | AN33: 66369649 | AO33: 64147462 | AP33: 53515286 | AQ33: 53213882 | AR33: 57619876 | AS33: 56584290 | AT33: 61545636 | AU33: 58094095 | AV33: 59088833 | AW33: 60307016 | AX33: 57512149 | AY33: 61546687 | AZ33: 63885011 | BA33: 67668433
A34: RECHAZO | B34: 9.9305897 | C34: 10.017097 | D34: 12.897199 | E34: 10.917682 | F34: 11.772249 | G34: 9.0450333 | H34: 10.358663 | I34: 12.469981 | J34: 8.7733015 | K34: 9.4036092 | L34: 11.899275 | M34: 10.387041 | N34: 9.799368 | O34: 11.493934 | P34: 13.770645 | Q34: 11.851935 | R34: 14.017439 | S34: 13.701073 | T34: 12.659305 | U34: 16.352861 | V34: 10.126501 | W34: 9.1623331 | X34: 10.296273 | Y34: 10.742051 | Z34: =+Z62 -> 34.638224 | AC34: =+$AC$35*(Z34/$Y$35) -> 32.81129 | AM34: RECHAZO | AN34: 13867484 | AO34: 15002860 | AP34: 13208811 | AQ34: 12190641 | AR34: 12579112 | AS34: 10552815 | AT34: 10121550 | AU34: 9162120.2 | AV34: 8594443.9 | AW34: 8536327.3 | AX34: 8041941.9 | AY34: 8480704.2 | AZ34: 8744103.9 | BA34: 9080434.6
A35: Total | B35: 595.78692 | C35: 535.12003 | D35: 770.79637 | E35: 715.5674 | F35: 811.48173 | G35: 774.53675 | H35: 914.91202 | I35: 945.68217 | J35: 935.926 | K35: =+SUM(K29:K34) -> 972.33634 | L35: =+SUM(L29:L34) -> 1184.8844 | M35: =SUM(M29:M34) -> 1205.1694 | N35: =SUM(N29:N34) -> 1105.346 | O35: =SUM(O29:O34) -> 1122.9562 | P35: =SUM(P29:P34) -> 1310.3091 | Q35: =SUM(Q29:Q34) -> 1172.98 | R35: =SUM(R29:R34) -> 1334.207 | S35: =SUM(S29:S34) -> 1253.844 | T35: =SUM(T29:T34) -> 1205.8695 | ... X35: =SUM(X29:X34) -> 1431.6943 | Y35: 1493.6797 | Z35: =SUM(Z29:Z34) -> 999.94158 | AC35: 1414.8981 | AM35: Total | AN35: 1.4477397e+09 | AO35: 1.5288093e+09 | AP35: 1.394336e+09 | AQ35: 1.4212965e+09 | AR35: 1.5531336e+09 | AS35: 1.4459864e+09 | AT35: 1.5463156e+09 | AU35: 1.4531471e+09 | AV35: 1.5508512e+09 | AW35: 1.5634121e+09 | AX35: 1.4900962e+09 | AY35: 1.5817088e+09 | AZ35: 1.6501952e+09 | BA35: 1.7527542e+09
AE36: (Para Power Bi)
B37: 202101 | C37: 202102 | D37: 202103 | E37: 202104 | F37: 202105 | G37: 202106 | H37: 202107 | I37: 202108 | J37: 202109 | K37: 202110 | L37: 202111 | M37: 202112 | N37: 202201 | O37: 202202 | P37: 202203 | Q37: 202004 | R37: 202005 | S37: 202206 | T37: 202207 | U37: 202208 | V37: 202209 | W37: 202210 | X37: =+X28 -> 202211 | Y37: =+Y28 -> 202212 | Z37: =+Z28 -> 202301 | AC37: =+AC28 -> 202303 Proy | AE37: PROYEC ENERO | AM37: PPTO | AN37: 202211 | AO37: 202212 | AP37: 202301 | AQ37: 202302 | AR37: 202302
A38: MUY ALTO | B38: =B29/B$35 -> 0.43156054 | C38: =C29/C$35 -> 0.40796896 | D38: =D29/D$35 -> 0.3977568 | E38: =E29/E$35 -> 0.42589877 | F38: =F29/F$35 -> 0.4382679 | G38: =G29/G$35 -> 0.45574732 | H38: =+H29/H$35 -> 0.45916604 | I38: =+I29/I$35 -> 0.43832834 | J38: =+J29/J$35 -> 0.46750963 | K38: =+K29/K$35 -> 0.4634053 | L38: =L29/$L$35 -> 0.45774365 | M38: =M29/$M$35 -> 0.45783367 | N38: =N29/$N$35 -> 0.44802776 | O38: =O29/$O$35 -> 0.44934403 | P38: =P29/P$35 -> 0.44680617 | Q38: =Q29/Q$35 -> 0.46180754 | R38: =R29/R$35 -> 0.45536444 | S38: =S29/S$35 -> 0.44782513 | T38: =T29/T$35 -> 0.44910582 | U38: =U29/U$35 -> 0.44223871 | V38: =V29/V$35 -> 0.43619038 | W38: =W29/W$35 -> 0.43840476 | X38: =X29/$X$35 -> 0.43119053 | Y38: =Y29/$Y$35 -> 0.43119053 | Z38: =Z29/$Z$35 -> 0.39728583 | AC38: =+Z38 -> 0.39728583 | AE38: 0.429 | AM38: MUY ALTO | AN38: 0.43347127 | AO38: 0.42569774 | AP38: 0.42743296 | AQ38: 0.4277685 | AR38: 0.43118991 | AS38: 0.43786192 | AT38: 0.44086771 | AU38: 0.44326811 | AV38: 0.44415135 | AW38: 0.44279495 | AX38: 0.44055663 | AY38: 0.44072213 | AZ38: 0.43817748 | BA38: 0.43386385
A39: ALTO | B39: =B30/B$35 -> 0.21612915 | C39: =C30/C$35 -> 0.22381946 | D39: =D30/D$35 -> 0.23289395 | E39: =E30/E$35 -> 0.22638137 | F39: =F30/F$35 -> 0.22124642 | G39: =G30/G$35 -> 0.22005049 | H39: =+H30/H$35 -> 0.22921268 | I39: =+I30/I$35 -> 0.22749148 | J39: =+J30/J$35 -> 0.22917859 | K39: =+K30/K$35 -> 0.22743139 | L39: =L30/$L$35 -> 0.23032101 | M39: =M30/$M$35 -> 0.23330482 | N39: =N30/$N$35 -> 0.23082257 | O39: =O30/$O$35 -> 0.22489861 | P39: =P30/$P$35 -> 0.22630553 | Q39: =Q30/Q$35 -> 0.22467281 | R39: =R30/R$35 -> 0.22205927 | S39: =S30/S$35 -> 0.2248532 | T39: =T30/T$35 -> 0.22478308 | U39: =U30/U$35 -> 0.22978228 | V39: =V30/V$35 -> 0.2319186 | W39: =W30/W$35 -> 0.23381908 | X39: =X30/$X$35 -> 0.23498507 | Y39: =Y30/$Y$35 -> 0.23498507 | Z39: =Z30/$Z$35 -> 0.2622543 | AC39: =+Z39 -> 0.2622543 | AE39: 0.236 | AM39: ALTO | AN39: 0.24772986 | AO39: 0.25480098 | AP39: 0.25658333 | AQ39: 0.25527679 | AR39: 0.25444819 | AS39: 0.25455085 | AT39: 0.25517555 | AU39: 0.25419584 | AV39: 0.25312059 | AW39: 0.25317694 | AX39: 0.25277422 | AY39: 0.25282997 | AZ39: 0.25437925 | BA39: 0.25675513
A40: MEDIO | B40: =B31/B$35 -> 0.10928568 | C40: =C31/C$35 -> 0.11115903 | D40: =D31/D$35 -> 0.11639558 | E40: =E31/E$35 -> 0.10688918 | F40: =F31/F$35 -> 0.10768152 | G40: =G31/G$35 -> 0.10621908 | H40: =+H31/H$35 -> 0.10565047 | I40: =+I31/I$35 -> 0.10946694 | J40: =+J31/J$35 -> 0.10598756 | K40: =+K31/K$35 -> 0.10744197 | L40: =L31/$L$35 -> 0.10694167 | M40: =M31/$M$35 -> 0.10836578 | N40: =N31/$N$35 -> 0.11431355 | O40: =O31/$O$35 -> 0.11525476 | P40: =P31/$P$35 -> 0.11398713 | Q40: =Q31/Q$35 -> 0.11003691 | R40: =R31/R$35 -> 0.11291544 | S40: =S31/S$35 -> 0.11263072 | T40: =T31/T$35 -> 0.11250343 | U40: =U31/U$35 -> 0.11224254 | V40: =V31/V$35 -> 0.11501368 | W40: =W31/W$35 -> 0.11622493 | X40: =X31/$X$35 -> 0.11661837 | Y40: =Y31/$Y$35 -> 0.11661837 | Z40: =Z31/$Z$35 -> 0.140784 | AC40: =+Z40 -> 0.140784 | AE40: 0.122 | AM40: MEDIO | AN40: 0.11375462 | AO40: 0.1217571 | AP40: 0.12160038 | AQ40: 0.12437614 | AR40: 0.12554993 | AS40: 0.1232466 | AT40: 0.12278736 | AU40: 0.12504486 | AV40: 0.12711153 | AW40: 0.12908721 | AX40: 0.13235929 | AY40: 0.13309213 | AZ40: 0.13398109 | BA40: 0.13678013
A41: BAJO | B41: =B32/B$35 -> 0.16549257 | C41: =C32/C$35 -> 0.17080228 | D41: =D32/D$35 -> 0.17080962 | E41: =E32/E$35 -> 0.163472 | F41: =F32/F$35 -> 0.15726117 | G41: =G32/G$35 -> 0.1513244 | H41: =+H32/H$35 -> 0.14527685 | I41: =+I32/I$35 -> 0.15552873 | J41: =+J32/J$35 -> 0.1423856 | K41: =+K32/K$35 -> 0.14614076 | L41: =L32/$L$35 -> 0.14743677 | M41: =M32/$M$35 -> 0.14867482 | N41: =N32/$N$35 -> 0.15270266 | O41: =O32/$O$35 -> 0.15283047 | P41: =P32/$P$35 -> 0.15412605 | Q41: =Q32/Q$35 -> 0.14766902 | R41: =R32/R$35 -> 0.15088799 | S41: =S32/S$35 -> 0.1548756 | T41: =T32/T$35 -> 0.1543899 | U41: =U32/U$35 -> 0.15592407 | V41: =V32/V$35 -> 0.15945359 | W41: =W32/W$35 -> 0.15678026 | X41: =X32/$X$35 -> 0.16048026 | Y41: =Y32/$Y$35 -> 0.16048026 | Z41: =Z32/$Z$35 -> 0.10369696 | AC41: =+Z41 -> 0.10369696 | AE41: 0.157 | AM41: BAJO | AN41: 0.1496219 | AO41: 0.14597164 | AP41: 0.14652966 | AQ41: 0.14656107 | AR41: 0.14361368 | AS41: 0.13791066 | AT41: 0.13482231 | AU41: 0.13120805 | AV41: 0.13197387 | AW41: 0.13090686 | AX41: 0.13031667 | AY41: 0.12908251 | AZ41: 0.12944975 | BA41: 0.12881331
A42: MUY BAJO | B42: =B33/B$35 -> 0.060864041 | C42: =C33/C$35 -> 0.067530925 | D42: =D33/D$35 -> 0.06541175 | E42: =E33/E$35 -> 0.062101294 | F42: =F33/F$35 -> 0.061035894 | G42: =G33/G$35 -> 0.053410321 | H42: =+H33/H$35 -> 0.049359571 | I42: =+I33/I$35 -> 0.055998285 | J42: =+J33/J$35 -> 0.045564691 | K42: =+K33/K$35 -> 0.045909429 | L42: =L33/$L$35 -> 0.047514344 | M42: =M33/$M$35 -> 0.043202163 | N42: =N33/$N$35 -> 0.045268024 | O42: =O33/$O$35 -> 0.047436711 | P42: =P33/$P$35 -> 0.048265659 | Q42: =Q33/Q$35 -> 0.045709603 | R42: =R33/R$35 -> 0.048266666 | S42: =S33/S$35 -> 0.048888101 | T42: =T33/T$35 -> 0.048719688 | U42: =U33/U$35 -> 0.049128357 | V42: =V33/V$35 -> 0.049684116 | W42: =W33/W$35 -> 0.048303035 | X42: =X33/$X$35 -> 0.049534094 | Y42: =Y33/$Y$35 -> 0.049534094 | Z42: =Z33/$Z$35 -> 0.061338667 | AC42: =+Z42 -> 0.061338667 | AE42: 0.047 | AM42: MUY BAJO | AN42: 0.045843633 | AO42: 0.041959101 | AP42: 0.038380481 | AQ42: 0.037440381 | AR42: 0.037099111 | AS42: 0.039131966 | AT42: 0.039801473 | AU42: 0.039978124 | AV42: 0.038100903 | AW42: 0.038573972 | AX42: 0.038596267 | AY42: 0.038911516 | AZ42: 0.038713609 | BA42: 0.038606916
A43: RECHAZO | B43: =B34/B$35 -> 0.016668022 | C43: =C34/C$35 -> 0.018719346 | D43: =D34/D$35 -> 0.016732303 | E43: =E34/E$35 -> 0.015257378 | F43: =F34/F$35 -> 0.014507103 | G43: =G34/G$35 -> 0.011677991 | H43: =+H34/H$35 -> 0.011322032 | I43: =+I34/I$35 -> 0.013186228 | J43: =+J34/J$35 -> 0.0093739264 | K43: =+K34/K$35 -> 0.0096711486 | L43: =L34/$L$35 -> 0.010042562 | M43: =M34/$M$35 -> 0.0086187396 | N43: =N34/$N$35 -> 0.0088654304 | O43: =O34/$O$35 -> 0.010235424 | P43: =P34/$P$35 -> 0.010509463 | Q43: =Q34/Q$35 -> 0.010104123 | R43: =R34/R$35 -> 0.010506195 | S43: =S34/S$35 -> 0.010927255 | T43: =T34/T$35 -> 0.010498072 | U43: =U34/U$35 -> 0.010684036 | V43: =V34/V$35 -> 0.0077396385 | W43: =W34/W$35 -> 0.0064679294 | X43: =X34/$X$35 -> 0.0071916696 | Y43: =Y34/$Y$35 -> 0.0071916696 | Z43: =Z34/$Z$35 -> 0.034640248 | AC43: =+Z43 -> 0.034640248 | AE43: =100%-SUM(AE38:AE42) -> 0.009 | AM43: RECHAZO | AN43: 0.0095787131 | AO43: 0.009813428 | AP43: 0.0094731906 | AQ43: 0.0085771272 | AR43: 0.0080991818 | AS43: 0.0072980043 | AT43: 0.0065455917 | AU43: 0.0063050191 | AV43: 0.005541759 | AW43: 0.0054600621 | AX43: 0.0053969281 | AY43: 0.0053617356 | AZ43: 0.0052988301 | BA43: 0.0051806663
AE44: =SUM(AE38:AE43) -> 1
...

Sheet PyCCuotas
A1: PASE A CUOTAS | H1: CONSUMO EN CUOTAS | N1: VS2 --> | O1: PASE A CUOTAS | V1: CONSUMO EN CUOTAS
A3: CODMES | B3: CA_NIVEL | C3: PONDERADO | D3: FACTU | E3: CLIENTES | H3: CODMES | I3: CA_NIVEL | J3: CLIENTES | K3: PONDCUOTAS | L3: FACTUTOTAL | O3: CODMES | P3: CA_NIVEL | Q3: PONDERADO | R3: FACTU | S3: CLIENTES | V3: CODMES | W3: CA_NIVEL | X3: CLIENTES | Y3: PONDCUOTAS | Z3: FACTUTOTAL
A4: 201901 | B4: MUY ALTO | C4: 16.452513 | D4: 2.0645966 | E4: 1.995 | H4: 201901 | I4: MUY BAJO | J4: 30.134 | K4: 137.10913 | L4: 18.976679 | O4: 201901 | Q4: 5.5413525 | R4: 0.65687864 | S4: 0.997 | V4: 201901 | W4: MUY BAJO | X4: 30.134 | Y4: 137.10913 | Z4: 18.976679
A5: 201901 | B5: MEDIO | C5: 39.682358 | D5: 4.7065481 | E5: 5.93 | H5: 201901 | I5: MUY ALTO | J5: 12.385 | K5: 81.506034 | L5: 9.2961916 | O5: 201901 | P5: RECHAZO | Q5: 16.959445 | R5: 2.2104552 | S5: 4.287 | V5: 201901 | W5: MUY ALTO | X5: 12.385 | Y5: 81.506034 | Z5: 9.2961916
A6: 201901 | C6: 6.1602097 | D6: 0.73054464 | E6: 0.997 | H6: 201901 | I6: ALTO | J6: 23.507 | K6: 160.91692 | L6: 17.553646 | O6: 201901 | P6: ALTO | Q6: 39.166753 | R6: 4.5194896 | S6: 5.178 | V6: 201901 | W6: ALTO | X6: 23.507 | Y6: 160.91692 | Z6: 17.553646
A7: 201901 | B7: MUY BAJO | C7: 45.784871 | D7: 6.0251464 | E7: 9.849 | H7: 201901 | J7: 4.385 | K7: 41.78528 | L7: 4.0141 | O7: 201901 | P7: BAJO | Q7: 52.690141 | R7: 6.7478142 | S7: 10.181 | V7: 201901 | X7: 4.385 | Y7: 41.78528 | Z7: 4.0141
A8: 201901 | B8: RECHAZO | C8: 17.949101 | D8: 2.357181 | E8: 4.287 | H8: 201901 | I8: BAJO | J8: 35.209 | K8: 167.32696 | L8: 22.685224 | O8: 201901 | P8: MEDIO | Q8: 37.667183 | R8: 4.4661819 | S8: 5.93 | V8: 201901 | W8: BAJO | X8: 35.209 | Y8: 167.32696 | Z8: 22.685224
A9: 201901 | B9: BAJO | C9: 56.621809 | D9: 7.1461336 | E9: 10.181 | H9: 201901 | I9: MEDIO | J9: 22.623 | K9: 131.86141 | L9: 15.642626 | O9: 201901 | P9: MUY ALTO | Q9: 15.428183 | R9: 1.9459622 | S9: 1.995 | V9: 201901 | W9: MEDIO | X9: 22.623 | Y9: 131.86141 | Z9: 15.642626
A10: 201901 | B10: ALTO | C10: 41.818508 | D10: 4.7969231 | E10: 5.178 | H10: 201901 | I10: RECHAZO | J10: 12.97 | K10: 44.304894 | L10: 7.2845794 | O10: 201901 | P10: MUY BAJO | Q10: 43.392493 | R10: 5.6970881 | S10: 9.849 | V10: 201901 | W10: RECHAZO | X10: 12.97 | Y10: 44.304894 | Z10: 7.2845794
A11: 201902 | B11: MUY ALTO | C11: 13.668879 | D11: 1.7124848 | E11: 1.886 | H11: 201902 | J11: 5.143 | K11: 54.030457 | L11: 5.0313002 | O11: 201902 | P11: BAJO | Q11: 50.115286 | R11: 5.9485315 | S11: 9.092 | V11: 201902 | X11: 5.143 | Y11: 54.030457 | Z11: 5.0313002
A12: 201902 | B12: RECHAZO | C12: 12.791993 | D12: 1.8553959 | E12: 4.063 | H12: 201902 | I12: MEDIO | J12: 22.975 | K12: 133.82364 | L12: 16.062186 | O12: 201902 | P12: MUY BAJO | Q12: 42.473384 | R12: 5.0282636 | S12: 8.618 | V12: 201902 | W12: MEDIO | X12: 22.975 | Y12: 133.82364 | Z12: 16.062186
A13: 201902 | B13: ALTO | C13: 35.018237 | D13: 4.1651611 | E13: 4.671 | H13: 201902 | I13: ALTO | J13: 23.555 | K13: 154.90828 | L13: 17.390728 | O13: 201902 | P13: RECHAZO | Q13: 12.635149 | R13: 1.8379236 | S13: 4.063 | V13: 201902 | W13: ALTO | X13: 23.555 | Y13: 154.90828 | Z13: 17.390728
A14: 201902 | B14: MEDIO | C14: 40.483279 | D14: 4.3003003 | E14: 5.427 | H14: 201902 | I14: MUY ALTO | J14: 12.744 | K14: 97.907503 | L14: 9.9222693 | O14: 201902 | P14: MEDIO | Q14: 40.125651 | R14: 4.2543399 | S14: 5.427 | V14: 201902 | W14: MUY ALTO | X14: 12.744 | Y14: 97.907503 | Z14: 9.9222693
A15: 201902 | C15: 5.084565 | D15: 0.60611709 | E15: 0.887 | H15: 201902 | I15: MUY BAJO | J15: 30.692 | K15: 134.6666 | L15: 19.502217 | O15: 201902 | Q15: 5.0186661 | R15: 0.59713515 | S15: 0.887 | V15: 201902 | W15: MUY BAJO | X15: 30.692 | Y15: 134.6666 | Z15: 19.502217
A16: 201902 | B16: MUY BAJO | C16: 43.37437 | D16: 5.0926377 | E16: 8.618 | H16: 201902 | I16: BAJO | J16: 35.009 | K16: 168.29381 | L16: 22.858628 | O16: 201902 | P16: ALTO | Q16: 34.510823 | R16: 4.109802 | S16: 4.671 | V16: 201902 | W16: BAJO | X16: 35.009 | Y16: 168.29381 | Z16: 22.858628
A17: 201902 | B17: BAJO | C17: 50.567256 | D17: 6.0079626 | E17: 9.092 | H17: 201902 | I17: RECHAZO | J17: 13.978 | K17: 40.803203 | L17: 7.4170187 | O17: 201902 | P17: MUY ALTO | Q17: 13.515841 | R17: 1.6812577 | S17: 1.886 | V17: 201902 | W17: RECHAZO | X17: 13.978 | Y17: 40.803203 | Z17: 7.4170187
A18: 201903 | B18: MUY BAJO | C18: 44.361215 | D18: 5.4181515 | E18: 8.91 | H18: 201903 | I18: MUY ALTO | J18: 13.49 | K18: 108.06584 | L18: 10.769031 | O18: 201903 | P18: MUY ALTO | Q18: 11.233506 | R18: 1.5317401 | S18: 1.741 | V18: 201903 | W18: MUY ALTO | X18: 13.49 | Y18: 108.06584 | Z18: 10.769031
A19: 201903 | B19: MEDIO | C19: 34.15128 | D19: 3.9592379 | E19: 5.088 | H19: 201903 | I19: MUY BAJO | J19: 35.628 | K19: 165.55103 | L19: 24.349444 | O19: 201903 | P19: RECHAZO | Q19: 13.099976 | R19: 1.8437988 | S19: 4.022 | V19: 201903 | W19: MUY BAJO | X19: 35.628 | Y19: 165.55103 | Z19: 24.349444
A20: 201903 | B20: MUY ALTO | C20: 11.303203 | D20: 1.5427652 | E20: 1.741 | H20: 201903 | J20: 7.53 | K20: 75.805435 | L20: 7.1142283 | O20: 201903 | P20: MEDIO | Q20: 33.760614 | R20: 3.9203165 | S20: 5.088 | V20: 201903 | X20: 7.53 | Y20: 75.805435 | Z20: 7.1142283
A21: 201903 | B21: RECHAZO | C21: 13.188354 | D21: 1.8626167 | E21: 4.022 | H21: 201903 | I21: MEDIO | J21: 25.358 | K21: 160.80613 | L21: 19.485894 | O21: 201903 | Q21: 8.5990666 | R21: 0.87595294 | S21: 1.377 | V21: 201903 | W21: MEDIO | X21: 25.358 | Y21: 160.80613 | Z21: 19.485894
A22: 201903 | C22: 8.660913 | D22: 0.88428285 | E22: 1.377 | H22: 201903 | I22: BAJO | J22: 39.897 | K22: 226.46096 | L22: 30.350779 | O22: 201903 | P22: ALTO | Q22: 34.128198 | R22: 4.0430521 | S22: 4.46 | V22: 201903 | W22: BAJO | X22: 39.897 | Y22: 226.46096 | Z22: 30.350779
A23: 201903 | B23: BAJO | C23: 54.719458 | D23: 6.6102085 | E23: 9.357 | H23: 201903 | I23: ALTO | J23: 25.616 | K23: 197.77605 | L23: 20.661572 | O23: 201903 | P23: BAJO | Q23: 53.680144 | R23: 6.5271495 | S23: 9.357 | V23: 201903 | W23: ALTO | X23: 25.616 | Y23: 197.77605 | Z23: 20.661572
A24: 201903 | B24: ALTO | C24: 34.674453 | D24: 4.0987171 | E24: 4.46 | H24: 201903 | I24: RECHAZO | J24: 15.779 | K24: 50.63542 | L24: 8.8925176 | O24: 201903 | P24: MUY BAJO | Q24: 43.759835 | R24: 5.364319 | S24: 8.91 | V24: 201903 | W24: RECHAZO | X24: 15.779 | Y24: 50.63542 | Z24: 8.8925176
A25: 201904 | B25: RECHAZO | C25: 16.164511 | D25: 2.2609276 | E25: 5.1 | H25: 201904 | J25: 6.725 | K25: 65.141737 | L25: 6.3891292 | O25: 201904 | P25: ALTO | Q25: 40.118264 | R25: 4.6788385 | S25: 5.587 | V25: 201904 | X25: 6.725 | Y25: 65.141737 | Z25: 6.3891292
A26: 201904 | B26: MUY BAJO | C26: 44.788854 | D26: 6.0380137 | E26: 10.532 | H26: 201904 | I26: MUY ALTO | J26: 12.837 | K26: 87.656201 | L26: 9.6211442 | O26: 201904 | P26: MUY BAJO | Q26: 43.584674 | R26: 5.9614512 | S26: 10.532 | V26: 201904 | W26: MUY ALTO | X26: 12.837 | Y26: 87.656201 | Z26: 9.6211442
A27: 201904 | B27: BAJO | C27: 58.185405 | D27: 7.1436001 | E27: 10.073 | H27: 201904 | I27: BAJO | J27: 35.524 | K27: 189.33006 | L27: 25.023598 | O27: 201904 | P27: RECHAZO | Q27: 15.895282 | R27: 2.2357748 | S27: 5.1 | V27: 201904 | W27: BAJO | X27: 35.524 | Y27: 189.33006 | Z27: 25.023598
A28: 201904 | B28: MUY ALTO | C28: 14.899086 | D28: 1.8981191 | E28: 2.067 | H28: 201904 | I28: RECHAZO | J28: 15.949 | K28: 45.098273 | L28: 8.3641918 | O28: 201904 | P28: MUY ALTO | Q28: 14.672339 | R28: 1.8584338 | S28: 2.067 | V28: 201904 | W28: RECHAZO | X28: 15.949 | Y28: 45.098273 | Z28: 8.3641918
A29: 201904 | B29: MEDIO | C29: 42.530903 | D29: 5.1190287 | E29: 6.283 | H29: 201904 | I29: ALTO | J29: 25.103 | K29: 182.54087 | L29: 19.254015 | O29: 201904 | P29: BAJO | Q29: 57.762378 | R29: 7.0814173 | S29: 10.073 | V29: 201904 | W29: ALTO | X29: 25.103 | Y29: 182.54087 | Z29: 19.254015
A30: 201904 | C30: 6.2767083 | D30: 0.82799533 | E30: 1.487 | H30: 201904 | I30: MUY BAJO | J30: 32.697 | K30: 131.91384 | L30: 20.025191 | O30: 201904 | Q30: 6.2312951 | R30: 0.82025554 | S30: 1.487 | V30: 201904 | W30: MUY BAJO | X30: 32.697 | Y30: 131.91384 | Z30: 20.025191
A31: 201904 | B31: ALTO | C31: 41.048809 | D31: 4.7550768 | E31: 5.587 | H31: 201904 | I31: MEDIO | J31: 23.879 | K31: 145.26955 | L31: 17.987598 | O31: 201904 | P31: MEDIO | Q31: 41.533512 | R31: 5.0253742 | S31: 6.283 | V31: 201904 | W31: MEDIO | X31: 23.879 | Y31: 145.26955 | Z31: 17.987598
A32: 201905 | B32: ALTO | C32: 43.183208 | D32: 5.5915011 | E32: 6.788 | H32: 201905 | I32: BAJO | J32: 38.277 | K32: 215.11019 | L32: 28.3706 | O32: 201905 | P32: ALTO | Q32: 42.627248 | R32: 5.5396129 | S32: 6.788 | V32: 201905 | W32: BAJO | X32: 38.277 | Y32: 215.11019 | Z32: 28.3706
A33: 201905 | B33: MUY BAJO | C33: 57.324477 | D33: 7.4355148 | E33: 12.25 | H33: 201905 | I33: RECHAZO | J33: 18.256 | K33: 55.67746 | L33: 9.719385 | O33: 201905 | P33: MUY ALTO | Q33: 13.478114 | R33: 2.1130174 | S33: 2.549 | V33: 201905 | W33: RECHAZO | X33: 18.256 | Y33: 55.67746 | Z33: 9.719385
A34: 201905 | B34: MUY ALTO | C34: 13.55025 | D34: 2.1306112 | E34: 2.549 | H34: 201905 | J34: 5.796 | K34: 50.011206 | L34: 5.4063602 | O34: 201905 | P34: MUY BAJO | Q34: 56.734038 | R34: 7.3704177 | S34: 12.25 | V34: 201905 | X34: 5.796 | Y34: 50.011206 | Z34: 5.4063602
A35: 201905 | B35: RECHAZO | C35: 19.392326 | D35: 2.9035342 | E35: 6.291 | H35: 201905 | I35: MUY BAJO | J35: 35.951 | K35: 159.27446 | L35: 23.681004 | O35: 201905 | P35: MEDIO | Q35: 47.132403 | R35: 5.9404994 | S35: 7.583 | V35: 201905 | W35: MUY BAJO | X35: 35.951 | Y35: 159.27446 | Z35: 23.681004
A36: 201905 | B36: MEDIO | C36: 48.281273 | D36: 6.0335333 | E36: 7.583 | H36: 201905 | I36: ALTO | J36: 27.495 | K36: 173.00963 | L36: 20.898348 | O36: 201905 | P36: BAJO | Q36: 68.98211 | R36: 8.7605619 | S36: 12.189 | V36: 201905 | W36: ALTO | X36: 27.495 | Y36: 173.00963 | Z36: 20.898348
A37: 201905 | B37: BAJO | C37: 69.879207 | D37: 8.8458228 | E37: 12.189 | H37: 201905 | I37: MUY ALTO | J37: 14.532 | K37: 89.844017 | L37: 10.701179 | O37: 201905 | Q37: 6.7161156 | R37: 0.817403 | S37: 1.36 | V37: 201905 | W37: MUY ALTO | X37: 14.532 | Y37: 89.844017 | Z37: 10.701179
A38: 201905 | C38: 6.7996527 | D38: 0.82432462 | E38: 1.36 | H38: 201905 | I38: MEDIO | J38: 26.147 | K38: 166.08539 | L38: 19.804477 | O38: 201905 | P38: RECHAZO | Q38: 19.228486 | R38: 2.8809301 | S38: 6.291 | V38: 201905 | W38: MEDIO | X38: 26.147 | Y38: 166.08539 | Z38: 19.804477
A39: 201906 | B39: MUY ALTO | C39: 17.502309 | D39: 2.2461536 | E39: 2.445 | H39: 201906 | I39: MUY BAJO | J39: 34.761 | K39: 149.2411 | L39: 21.740745 | O39: 201906 | P39: BAJO | Q39: 67.347101 | R39: 8.5110245 | S39: 11.794 | V39: 201906 | W39: MUY BAJO | X39: 34.761 | Y39: 149.2411 | Z39: 21.740745
A40: 201906 | B40: RECHAZO | C40: 19.63499 | D40: 3.1635077 | E40: 6.639 | H40: 201906 | I40: ALTO | J40: 25.625 | K40: 159.90253 | L40: 19.106063 | O40: 201906 | P40: ALTO | Q40: 45.368861 | R40: 5.5687754 | S40: 6.671 | V40: 201906 | W40: ALTO | X40: 25.625 | Y40: 159.90253 | Z40: 19.106063
A41: 201906 | C41: 5.5381387 | D41: 0.7033129 | E41: 1.173 | H41: 201906 | I41: BAJO | J41: 36.637 | K41: 181.69185 | L41: 25.804319 | O41: 201906 | P41: MEDIO | Q41: 52.550502 | R41: 5.988895 | S41: 7.32 | V41: 201906 | W41: BAJO | X41: 36.637 | Y41: 181.69185 | Z41: 25.804319
...

Sheet CuotasaAnterior
A1: PASE A CUOTAS | J1: COMPRA EN CUOTAS
A3: MES ACTUAL | B3: 202107
A5: CODMES | B5: CA_NIVEL | C5: NumCuotas | D5: FactuPonderada | E5: FactuCuotas | F5: ClientesCuotas | G5: %FactuCuota | H5: %Cuentas | J5: CODMES | K5: CA_NIVEL | L5: NumCuotas | M5: FactuPonderada | N5: FactuCuotas | O5: ClientesCuotas | P5: %FactuCuota | Q5: %Cuentas | S5: % CuotasT
A6: 201901 | C6: 8.066582 | D6: 224.46937 | E6: 27.827073 | F6: 38.417 | G6: =IF(A6="","",E6/IF(A6=$B$3,Resumen!#REF!,VLOOKUP(A6,Graf_PowerBI!$A$4:$D$39,3,0))) -> 0.044983893 | H6: =IF(A6="","",F6/IF(A6=$B$3,Resumen!#REF!,VLOOKUP(A6,Graf_PowerBI!$A$4:$D$39,4,0))) -> 0.063723205 | J6: 201901 | L6: 8.0124278 | M6: 764.81064 | N6: 95.453046 | O6: 141.213 | P6: =IF(J6="","",N6/IF(J6=$B$3,Resumen!#REF!,VLOOKUP(J6,Graf_PowerBI!$A$4:$D$39,3,0))) -> 0.15430475 | Q6: =IF(J6="","",O6/IF(J6=$B$3,Resumen!#REF!,VLOOKUP(J6,Graf_PowerBI!$A$4:$D$39,4,0))) -> 0.23423341 | S6: =IF(A6="","",P6+G6) -> 0.19928864
A7: 201902 | C7: 8.4662205 | D7: 200.98858 | E7: 23.74006 | F7: 34.644 | G7: =IF(A7="","",E7/IF(A7=$B$3,Resumen!#REF!,VLOOKUP(A7,Graf_PowerBI!$A$4:$D$39,3,0))) -> 0.038373598 | H7: =IF(A7="","",F7/IF(A7=$B$3,Resumen!#REF!,VLOOKUP(A7,Graf_PowerBI!$A$4:$D$39,4,0))) -> 0.057023969 | J7: 201902 | L7: 7.9893946 | M7: 784.43349 | N7: 98.184347 | O7: 144.096 | P7: =IF(J7="","",N7/IF(J7=$B$3,Resumen!#REF!,VLOOKUP(J7,Graf_PowerBI!$A$4:$D$39,3,0))) -> 0.15870586 | Q7: =IF(J7="","",O7/IF(J7=$B$3,Resumen!#REF!,VLOOKUP(J7,Graf_PowerBI!$A$4:$D$39,4,0))) -> 0.23718179 | S7: =IF(A7="","",P7+G7) -> 0.19707946
A8: 201903 | C8: 8.2482377 | D8: 201.05888 | E8: 24.37598 | F8: 34.955 | G8: =IF(A8="","",E8/IF(A8=$B$3,Resumen!#REF!,VLOOKUP(A8,Graf_PowerBI!$A$4:$D$39,3,0))) -> 0.034886389 | H8: =IF(A8="","",F8/IF(A8=$B$3,Resumen!#REF!,VLOOKUP(A8,Graf_PowerBI!$A$4:$D$39,4,0))) -> 0.055917085 | J8: 201903 | L8: 8.0995955 | M8: 985.10087 | N8: 121.62347 | O8: 163.298 | P8: =IF(J8="","",N8/IF(J8=$B$3,Resumen!#REF!,VLOOKUP(J8,Graf_PowerBI!$A$4:$D$39,3,0))) -> 0.17406494 | Q8: =IF(J8="","",O8/IF(J8=$B$3,Resumen!#REF!,VLOOKUP(J8,Graf_PowerBI!$A$4:$D$39,4,0))) -> 0.26122581 | S8: =IF(A8="","",P8+G8) -> 0.20895133
A9: 201904 | C9: 7.984031 | D9: 223.89428 | E9: 28.042761 | F9: 41.129 | G9: =IF(A9="","",E9/IF(A9=$B$3,Resumen!#REF!,VLOOKUP(A9,Graf_PowerBI!$A$4:$D$39,3,0))) -> 0.042123079 | H9: =IF(A9="","",F9/IF(A9=$B$3,Resumen!#REF!,VLOOKUP(A9,Graf_PowerBI!$A$4:$D$39,4,0))) -> 0.065169718 | J9: 201904 | L9: 7.9402953 | M9: 846.95053 | N9: 106.66487 | O9: 152.714 | P9: =IF(J9="","",N9/IF(J9=$B$3,Resumen!#REF!,VLOOKUP(J9,Graf_PowerBI!$A$4:$D$39,3,0))) -> 0.16022147 | Q9: =IF(J9="","",O9/IF(J9=$B$3,Resumen!#REF!,VLOOKUP(J9,Graf_PowerBI!$A$4:$D$39,4,0))) -> 0.24197837 | S9: =IF(A9="","",P9+G9) -> 0.20234455
A10: 201905 | C10: 7.6532386 | D10: 258.41039 | E10: 33.764842 | F10: 49.01 | G10: =IF(A10="","",E10/IF(A10=$B$3,Resumen!#REF!,VLOOKUP(A10,Graf_PowerBI!$A$4:$D$39,3,0))) -> 0.046630654 | H10: =IF(A10="","",F10/IF(A10=$B$3,Resumen!#REF!,VLOOKUP(A10,Graf_PowerBI!$A$4:$D$39,4,0))) -> 0.076164102 | J10: 201905 | L10: 7.6657276 | M10: 909.01235 | N10: 118.58135 | O10: 166.454 | P10: =IF(J10="","",N10/IF(J10=$B$3,Resumen!#REF!,VLOOKUP(J10,Graf_PowerBI!$A$4:$D$39,3,0))) -> 0.16376579 | Q10: =IF(J10="","",O10/IF(J10=$B$3,Resumen!#REF!,VLOOKUP(J10,Graf_PowerBI!$A$4:$D$39,4,0))) -> 0.25867822 | S10: =IF(A10="","",P10+G10) -> 0.21039645
A11: 201906 | C11: 7.8688203 | D11: 283.50043 | E11: 36.028327 | F11: 48.143 | G11: =IF(A11="","",E11/IF(A11=$B$3,Resumen!#REF!,VLOOKUP(A11,Graf_PowerBI!$A$4:$D$39,3,0))) -> 0.051922878 | H11: =IF(A11="","",F11/IF(A11=$B$3,Resumen!#REF!,VLOOKUP(A11,Graf_PowerBI!$A$4:$D$39,4,0))) -> 0.074503316 | J11: 201906 | L11: 7.3464946 | M11: 788.10696 | N11: 107.2766 | O11: 158.692 | P11: =IF(J11="","",N11/IF(J11=$B$3,Resumen!#REF!,VLOOKUP(J11,Graf_PowerBI!$A$4:$D$39,3,0))) -> 0.15460362 | Q11: =IF(J11="","",O11/IF(J11=$B$3,Resumen!#REF!,VLOOKUP(J11,Graf_PowerBI!$A$4:$D$39,4,0))) -> 0.24558254 | S11: =IF(A11="","",P11+G11) -> 0.2065265
A12: 201907 | C12: 7.9088808 | D12: 313.09577 | E12: 39.587873 | F12: 48.534 | G12: =IF(A12="","",E12/IF(A12=$B$3,Resumen!#REF!,VLOOKUP(A12,Graf_PowerBI!$A$4:$D$39,3,0))) -> 0.051611048 | H12: =IF(A12="","",F12/IF(A12=$B$3,Resumen!#REF!,VLOOKUP(A12,Graf_PowerBI!$A$4:$D$39,4,0))) -> 0.073776809 | J12: 201907 | L12: 7.5266607 | M12: 729.38732 | N12: 96.907161 | O12: 153.899 | P12: =IF(J12="","",N12/IF(J12=$B$3,Resumen!#REF!,VLOOKUP(J12,Graf_PowerBI!$A$4:$D$39,3,0))) -> 0.12633869 | Q12: =IF(J12="","",O12/IF(J12=$B$3,Resumen!#REF!,VLOOKUP(J12,Graf_PowerBI!$A$4:$D$39,4,0))) -> 0.23394274 | S12: =IF(A12="","",P12+G12) -> 0.17794974
A13: 201908 | C13: 8.2582491 | D13: 381.93012 | E13: 46.248317 | F13: 54.977 | G13: =IF(A13="","",E13/IF(A13=$B$3,Resumen!#REF!,VLOOKUP(A13,Graf_PowerBI!$A$4:$D$39,3,0))) -> 0.062575192 | H13: =IF(A13="","",F13/IF(A13=$B$3,Resumen!#REF!,VLOOKUP(A13,Graf_PowerBI!$A$4:$D$39,4,0))) -> 0.082931826 | J13: 201908 | L13: 7.615164 | M13: 735.87248 | N13: 96.63252 | O13: 155.76 | P13: =IF(J13="","",N13/IF(J13=$B$3,Resumen!#REF!,VLOOKUP(J13,Graf_PowerBI!$A$4:$D$39,3,0))) -> 0.13074635 | Q13: =IF(J13="","",O13/IF(J13=$B$3,Resumen!#REF!,VLOOKUP(J13,Graf_PowerBI!$A$4:$D$39,4,0))) -> 0.23496119 | S13: =IF(A13="","",P13+G13) -> 0.19332154
A14: 201909 | C14: 8.157486 | D14: 327.6703 | E14: 40.168049 | F14: 54.455 | G14: =IF(A14="","",E14/IF(A14=$B$3,Resumen!#REF!,VLOOKUP(A14,Graf_PowerBI!$A$4:$D$39,3,0))) -> 0.056628844 | H14: =IF(A14="","",F14/IF(A14=$B$3,Resumen!#REF!,VLOOKUP(A14,Graf_PowerBI!$A$4:$D$39,4,0))) -> 0.081795951 | J14: 201909 | L14: 7.857218 | M14: 701.577 | N14: 89.290764 | O14: 150.564 | P14: =IF(J14="","",N14/IF(J14=$B$3,Resumen!#REF!,VLOOKUP(J14,Graf_PowerBI!$A$4:$D$39,3,0))) -> 0.12588196 | Q14: =IF(J14="","",O14/IF(J14=$B$3,Resumen!#REF!,VLOOKUP(J14,Graf_PowerBI!$A$4:$D$39,4,0))) -> 0.22615968 | S14: =IF(A14="","",P14+G14) -> 0.1825108
A15: 201910 | C15: 8.1662172 | D15: 336.4751 | E15: 41.2033 | F15: 55.312 | G15: =IF(A15="","",E15/IF(A15=$B$3,Resumen!#REF!,VLOOKUP(A15,Graf_PowerBI!$A$4:$D$39,3,0))) -> 0.054810342 | H15: =IF(A15="","",F15/IF(A15=$B$3,Resumen!#REF!,VLOOKUP(A15,Graf_PowerBI!$A$4:$D$39,4,0))) -> 0.082250406 | J15: 201910 | L15: 7.7393628 | M15: 692.18519 | N15: 89.436973 | O15: 151.034 | P15: =IF(J15="","",N15/IF(J15=$B$3,Resumen!#REF!,VLOOKUP(J15,Graf_PowerBI!$A$4:$D$39,3,0))) -> 0.11897278 | Q15: =IF(J15="","",O15/IF(J15=$B$3,Resumen!#REF!,VLOOKUP(J15,Graf_PowerBI!$A$4:$D$39,4,0))) -> 0.22459155 | S15: =IF(A15="","",P15+G15) -> 0.17378312
A16: 201911 | C16: 7.9207204 | D16: 363.2419 | E16: 45.859705 | F16: 54.519 | G16: =IF(A16="","",E16/IF(A16=$B$3,Resumen!#REF!,VLOOKUP(A16,Graf_PowerBI!$A$4:$D$39,3,0))) -> 0.058861608 | H16: =IF(A16="","",F16/IF(A16=$B$3,Resumen!#REF!,VLOOKUP(A16,Graf_PowerBI!$A$4:$D$39,4,0))) -> 0.080870846 | J16: 201911 | L16: 8.5526016 | M16: 796.26571 | N16: 93.102163 | O16: 145.763 | P16: =IF(J16="","",N16/IF(J16=$B$3,Resumen!#REF!,VLOOKUP(J16,Graf_PowerBI!$A$4:$D$39,3,0))) -> 0.119498 | Q16: =IF(J16="","",O16/IF(J16=$B$3,Resumen!#REF!,VLOOKUP(J16,Graf_PowerBI!$A$4:$D$39,4,0))) -> 0.21621778 | S16: =IF(A16="","",P16+G16) -> 0.17835961
A17: 201912 | C17: 7.9631879 | D17: 420.58069 | E17: 52.815618 | F17: 56.381 | G17: =IF(A17="","",E17/IF(A17=$B$3,Resumen!#REF!,VLOOKUP(A17,Graf_PowerBI!$A$4:$D$39,3,0))) -> 0.062014764 | H17: =IF(A17="","",F17/IF(A17=$B$3,Resumen!#REF!,VLOOKUP(A17,Graf_PowerBI!$A$4:$D$39,4,0))) -> 0.083014806 | J17: 201912 | L17: 7.8981925 | M17: 899.7026 | N17: 113.91247 | O17: 167.331 | P17: =IF(J17="","",N17/IF(J17=$B$3,Resumen!#REF!,VLOOKUP(J17,Graf_PowerBI!$A$4:$D$39,3,0))) -> 0.13375314 | Q17: =IF(J17="","",O17/IF(J17=$B$3,Resumen!#REF!,VLOOKUP(J17,Graf_PowerBI!$A$4:$D$39,4,0))) -> 0.24637645 | S17: =IF(A17="","",P17+G17) -> 0.1957679
... A35: 202106 | C35: 7.6451069 | D35: 204.33849 | E35: 26.728009 | F35: 30.607 | G35: =IF(A35="","",E35/IF(A35=$B$3,Resumen!#REF!,VLOOKUP(A35,Graf_PowerBI!$A$4:$D$39,3,0))) -> 0.033248688 | H35: =IF(A35="","",F35/IF(A35=$B$3,Resumen!#REF!,VLOOKUP(A35,Graf_PowerBI!$A$4:$D$39,4,0))) -> 0.052211576 | J35: 202106 | L35: 6.5568659 | M35: 403.33392 | N35: 61.513217 | O35: 89.452 | P35: =IF(J35="","",N35/IF(J35=$B$3,Resumen!#REF!,VLOOKUP(J35,Graf_PowerBI!$A$4:$D$39,3,0))) -> 0.076520244 | Q35: =IF(J35="","",O35/IF(J35=$B$3,Resumen!#REF!,VLOOKUP(J35,Graf_PowerBI!$A$4:$D$39,4,0))) -> 0.15259352 | S35: =IF(A35="","",P35+G35) -> 0.10976893
A36: 202106 | B36: MUY ALTO | C36: 7.2179694 | D36: 28.644233 | E36: 3.9684614 | F36: 3.163 | G36: =IF(A36="","",E36/IF(A36=$B$3,Resumen!#REF!,VLOOKUP(A36,Graf_PowerBI!$A$4:$D$39,3,0))) -> 0.0049366242 | H36: =IF(A36="","",F36/IF(A36=$B$3,Resumen!#REF!,VLOOKUP(A36,Graf_PowerBI!$A$4:$D$39,4,0))) -> 0.0053956681 | J36: 202106 | K36: MUY ALTO | L36: 7.8623722 | M36: 84.946681 | N36: 10.804205 | O36: 11.779 | P36: =IF(J36="","",N36/IF(J36=$B$3,Resumen!#REF!,VLOOKUP(J36,Graf_PowerBI!$A$4:$D$39,3,0))) -> 0.013440045 | Q36: =IF(J36="","",O36/IF(J36=$B$3,Resumen!#REF!,VLOOKUP(J36,Graf_PowerBI!$A$4:$D$39,4,0))) -> 0.020093448 | S36: =IF(A36="","",P36+G36) -> 0.018376669
A37: 202106 | B37: ALTO | C37: 8.91437 | D37: 46.431104 | E37: 5.2085682 | F37: 4.507 | G37: =IF(A37="","",E37/IF(A37=$B$3,Resumen!#REF!,VLOOKUP(A37,Graf_PowerBI!$A$4:$D$39,3,0))) -> 0.0064792727 | H37: =IF(A37="","",F37/IF(A37=$B$3,Resumen!#REF!,VLOOKUP(A37,Graf_PowerBI!$A$4:$D$39,4,0))) -> 0.0076883579 | J37: 202106 | K37: ALTO | L37: 6.9508079 | M37: 83.185752 | N37: 11.967782 | O37: 14.98 | P37: =IF(J37="","",N37/IF(J37=$B$3,Resumen!#REF!,VLOOKUP(J37,Graf_PowerBI!$A$4:$D$39,3,0))) -> 0.014887493 | Q37: =IF(J37="","",O37/IF(J37=$B$3,Resumen!#REF!,VLOOKUP(J37,Graf_PowerBI!$A$4:$D$39,4,0))) -> 0.025553939 | S37: =IF(A37="","",P37+G37) -> 0.021366766
A38: 202106 | B38: MEDIO | C38: 7.7846328 | D38: 28.152205 | E38: 3.6163819 | F38: 3.822 | G38: =IF(A38="","",E38/IF(A38=$B$3,Resumen!#REF!,VLOOKUP(A38,Graf_PowerBI!$A$4:$D$39,3,0))) -> 0.0044986498 | H38: =IF(A38="","",F38/IF(A38=$B$3,Resumen!#REF!,VLOOKUP(A38,Graf_PowerBI!$A$4:$D$39,4,0))) -> 0.0065198367 | J38: 202106 | K38: MEDIO | L38: 6.2112253 | M38: 50.299783 | N38: 8.0982061 | O38: 11.372 | P38: =IF(J38="","",N38/IF(J38=$B$3,Resumen!#REF!,VLOOKUP(J38,Graf_PowerBI!$A$4:$D$39,3,0))) -> 0.010073879 | Q38: =IF(J38="","",O38/IF(J38=$B$3,Resumen!#REF!,VLOOKUP(J38,Graf_PowerBI!$A$4:$D$39,4,0))) -> 0.019399158 | S38: =IF(A38="","",P38+G38) -> 0.014572529
A39: 202106 | B39: BAJO | C39: 7.4626 | D39: 60.252567 | E39: 8.0739377 | F39: 9.942 | G39: =IF(A39="","",E39/IF(A39=$B$3,Resumen!#REF!,VLOOKUP(A39,Graf_PowerBI!$A$4:$D$39,3,0))) -> 0.01004369 | H39: =IF(A39="","",F39/IF(A39=$B$3,Resumen!#REF!,VLOOKUP(A39,Graf_PowerBI!$A$4:$D$39,4,0))) -> 0.016959764 | J39: 202106 | K39: BAJO | L39: 6.2128413 | M39: 108.94701 | N39: 17.535779 | O39: 27.249 | P39: =IF(J39="","",N39/IF(J39=$B$3,Resumen!#REF!,VLOOKUP(J39,Graf_PowerBI!$A$4:$D$39,3,0))) -> 0.021813882 | Q39: =IF(J39="","",O39/IF(J39=$B$3,Resumen!#REF!,VLOOKUP(J39,Graf_PowerBI!$A$4:$D$39,4,0))) -> 0.046483263 | S39: =IF(A39="","",P39+G39) -> 0.031857572
A40: 202106 | B40: MUY BAJO | C40: 6.8215337 | D40: 29.446743 | E40: 4.3167336 | F40: 6.547 | G40: =IF(A40="","",E40/IF(A40=$B$3,Resumen!#REF!,VLOOKUP(A40,Graf_PowerBI!$A$4:$D$39,3,0))) -> 0.0053698623 | H40: =IF(A40="","",F40/IF(A40=$B$3,Resumen!#REF!,VLOOKUP(A40,Graf_PowerBI!$A$4:$D$39,4,0))) -> 0.011168334 | J40: 202106 | K40: MUY BAJO | L40: 5.6232497 | M40: 49.394813 | N40: 8.7840334 | O40: 16.213 | P40: =IF(J40="","",N40/IF(J40=$B$3,Resumen!#REF!,VLOOKUP(J40,Graf_PowerBI!$A$4:$D$39,3,0))) -> 0.010927024 | Q40: =IF(J40="","",O40/IF(J40=$B$3,Resumen!#REF!,VLOOKUP(J40,Graf_PowerBI!$A$4:$D$39,4,0))) -> 0.027657277 | S40: =IF(A40="","",P40+G40) -> 0.016296886
A41: 202106 | B41: RECHAZO | C41: 6.9123925 | D41: 7.854974 | E41: 1.1363611 | F41: 2.048 | G41: =IF(A41="","",E41/IF(A41=$B$3,Resumen!#REF!,VLOOKUP(A41,Graf_PowerBI!$A$4:$D$39,3,0))) -> 0.0014135926 | H41: =IF(A41="","",F41/IF(A41=$B$3,Resumen!#REF!,VLOOKUP(A41,Graf_PowerBI!$A$4:$D$39,4,0))) -> 0.0034936226 | J41: 202106 | K41: RECHAZO | L41: 4.9729318 | M41: 10.124437 | N41: 2.035909 | O41: 4.785 | P41: =IF(J41="","",N41/IF(J41=$B$3,Resumen!#REF!,VLOOKUP(J41,Graf_PowerBI!$A$4:$D$39,3,0))) -> 0.002532598 | Q41: =IF(J41="","",O41/IF(J41=$B$3,Resumen!#REF!,VLOOKUP(J41,Graf_PowerBI!$A$4:$D$39,4,0))) -> 0.0081625899 | S41: =IF(A41="","",P41+G41) -> 0.0039461907
A42: 202106 | B42: (en blanco) | C42: 8.726601 | D42: 3.5566618 | E42: 0.40756553 | F42: 0.578 | G42: =IF(A42="","",E42/IF(A42=$B$3,Resumen!#REF!,VLOOKUP(A42,Graf_PowerBI!$A$4:$D$39,3,0))) -> 0.00050699696 | H42: =IF(A42="","",F42/IF(A42=$B$3,Resumen!#REF!,VLOOKUP(A42,Graf_PowerBI!$A$4:$D$39,4,0))) -> 0.0009859931 | J42: 202106 | K42: (en blanco) | L42: 7.1855104 | M42: 16.435439 | N42: 2.287303 | O42: 3.074 | P42: =IF(J42="","",N42/IF(J42=$B$3,Resumen!#REF!,VLOOKUP(J42,Graf_PowerBI!$A$4:$D$39,3,0))) -> 0.0028453231 | Q42: =IF(J42="","",O42/IF(J42=$B$3,Resumen!#REF!,VLOOKUP(J42,Graf_PowerBI!$A$4:$D$39,4,0))) -> 0.0052438456 | S42: =IF(A42="","",P42+G42) -> 0.0033523201
A43: 202107 | C43: 6.9613322 | D43: 59.157783 | E43: 8.4980548 | F43: 11.288 | G43: =IF(A43="","",E43/IF(A43=$B$3,Resumen!#REF!,VLOOKUP(A43,Graf_PowerBI!$A$4:$D$39,3,0))) -> #REF! | H43: =IF(A43="","",F43/IF(A43=$B$3,Resumen!#REF!,VLOOKUP(A43,Graf_PowerBI!$A$4:$D$39,4,0))) -> #REF! | J43: 202107 | L43: 6.4275388 | M43: 67.142563 | N43: 10.446077 | O43: 21.051 | P43: =IF(J43="","",N43/IF(J43=$B$3,Resumen!#REF!,VLOOKUP(J43,Graf_PowerBI!$A$4:$D$39,3,0))) -> #REF! | Q43: =IF(J43="","",O43/IF(J43=$B$3,Resumen!#REF!,VLOOKUP(J43,Graf_PowerBI!$A$4:$D$39,4,0))) -> #REF! | S43: =IF(A43="","",P43+G43) -> #REF!
G44: =IF(A44="","",E44/IF(A44=$B$3,Resumen!#REF!,VLOOKUP(A44,Graf_PowerBI!$A$4:$D$39,3,0))) | H44: =IF(A44="","",F44/IF(A44=$B$3,Resumen!#REF!,VLOOKUP(A44,Graf_PowerBI!$A$4:$D$39,4,0))) | P44: =IF(J44="","",N44/IF(J44=$B$3,Resumen!#REF!,VLOOKUP(J44,Graf_PowerBI!$A$4:$D$39,3,0))) | Q44: =IF(J44="","",O44/IF(J44=$B$3,Resumen!#REF!,VLOOKUP(J44,Graf_PowerBI!$A$4:$D$39,4,0))) | S44: =IF(A44="","",P44+G44)
G45: =IF(A45="","",E45/IF(A45=$B$3,Resumen!#REF!,VLOOKUP(A45,Graf_PowerBI!$A$4:$D$39,3,0))) | H45: =IF(A45="","",F45/IF(A45=$B$3,Resumen!#REF!,VLOOKUP(A45,Graf_PowerBI!$A$4:$D$39,4,0))) | P45: =IF(J45="","",N45/IF(J45=$B$3,Resumen!#REF!,VLOOKUP(J45,Graf_PowerBI!$A$4:$D$39,3,0))) | Q45: =IF(J45="","",O45/IF(J45=$B$3,Resumen!#REF!,VLOOKUP(J45,Graf_PowerBI!$A$4:$D$39,4,0))) | S45: =IF(A45="","",P45+G45)
G46: =IF(A46="","",E46/IF(A46=$B$3,Resumen!#REF!,VLOOKUP(A46,Graf_PowerBI!$A$4:$D$39,3,0))) | H46: =IF(A46="","",F46/IF(A46=$B$3,Resumen!#REF!,VLOOKUP(A46,Graf_PowerBI!$A$4:$D$39,4,0))) | P46: =IF(J46="","",N46/IF(J46=$B$3,Resumen!#REF!,VLOOKUP(J46,Graf_PowerBI!$A$4:$D$39,3,0))) | Q46: =IF(J46="","",O46/IF(J46=$B$3,Resumen!#REF!,VLOOKUP(J46,Graf_PowerBI!$A$4:$D$39,4,0))) | S46: =IF(A46="","",P46+G46)
G47: =IF(A47="","",E47/IF(A47=$B$3,Resumen!#REF!,VLOOKUP(A47,Graf_PowerBI!$A$4:$D$39,3,0))) | H47: =IF(A47="","",F47/IF(A47=$B$3,Resumen!#REF!,VLOOKUP(A47,Graf_PowerBI!$A$4:$D$39,4,0))) | P47: =IF(J47="","",N47/IF(J47=$B$3,Resumen!#REF!,VLOOKUP(J47,Graf_PowerBI!$A$4:$D$39,3,0))) | Q47: =IF(J47="","",O47/IF(J47=$B$3,Resumen!#REF!,VLOOKUP(J47,Graf_PowerBI!$A$4:$D$39,4,0))) | S47: =IF(A47="","",P47+G47)
G48: =IF(A48="","",E48/IF(A48=$B$3,Resumen!#REF!,VLOOKUP(A48,Graf_PowerBI!$A$4:$D$39,3,0))) | H48: =IF(A48="","",F48/IF(A48=$B$3,Resumen!#REF!,VLOOKUP(A48,Graf_PowerBI!$A$4:$D$39,4,0))) | P48: =IF(J48="","",N48/IF(J48=$B$3,Resumen!#REF!,VLOOKUP(J48,Graf_PowerBI!$A$4:$D$39,3,0))) | Q48: =IF(J48="","",O48/IF(J48=$B$3,Resumen!#REF!,VLOOKUP(J48,Graf_PowerBI!$A$4:$D$39,4,0))) | S48: =IF(A48="","",P48+G48)
G49: =IF(A49="","",E49/IF(A49=$B$3,Resumen!#REF!,VLOOKUP(A49,Graf_PowerBI!$A$4:$D$39,3,0))) | H49: =IF(A49="","",F49/IF(A49=$B$3,Resumen!#REF!,VLOOKUP(A49,Graf_PowerBI!$A$4:$D$39,4,0))) | P49: =IF(J49="","",N49/IF(J49=$B$3,Resumen!#REF!,VLOOKUP(J49,Graf_PowerBI!$A$4:$D$39,3,0))) | Q49: =IF(J49="","",O49/IF(J49=$B$3,Resumen!#REF!,VLOOKUP(J49,Graf_PowerBI!$A$4:$D$39,4,0))) | S49: =IF(A49="","",P49+G49)
G50: =IF(A50="","",E50/IF(A50=$B$3,Resumen!#REF!,VLOOKUP(A50,Graf_PowerBI!$A$4:$D$39,3,0))) | H50: =IF(A50="","",F50/IF(A50=$B$3,Resumen!#REF!,VLOOKUP(A50,Graf_PowerBI!$A$4:$D$39,4,0))) | P50: =IF(J50="","",N50/IF(J50=$B$3,Resumen!#REF!,VLOOKUP(J50,Graf_PowerBI!$A$4:$D$39,3,0))) | Q50: =IF(J50="","",O50/IF(J50=$B$3,Resumen!#REF!,VLOOKUP(J50,Graf_PowerBI!$A$4:$D$39,4,0))) | S50: =IF(A50="","",P50+G50)
G51: =IF(A51="","",E51/IF(A51=$B$3,Resumen!#REF!,VLOOKUP(A51,Graf_PowerBI!$A$4:$D$39,3,0))) | H51: =IF(A51="","",F51/IF(A51=$B$3,Resumen!#REF!,VLOOKUP(A51,Graf_PowerBI!$A$4:$D$39,4,0))) | P51: =IF(J51="","",N51/IF(J51=$B$3,Resumen!#REF!,VLOOKUP(J51,Graf_PowerBI!$A$4:$D$39,3,0))) | Q51: =IF(J51="","",O51/IF(J51=$B$3,Resumen!#REF!,VLOOKUP(J51,Graf_PowerBI!$A$4:$D$39,4,0))) | S51: =IF(A51="","",P51+G51)
G52: =IF(A52="","",E52/IF(A52=$B$3,Resumen!#REF!,VLOOKUP(A52,Graf_PowerBI!$A$4:$D$39,3,0))) | H52: =IF(A52="","",F52/IF(A52=$B$3,Resumen!#REF!,VLOOKUP(A52,Graf_PowerBI!$A$4:$D$39,4,0))) | P52: =IF(J52="","",N52/IF(J52=$B$3,Resumen!#REF!,VLOOKUP(J52,Graf_PowerBI!$A$4:$D$39,3,0))) | Q52: =IF(J52="","",O52/IF(J52=$B$3,Resumen!#REF!,VLOOKUP(J52,Graf_PowerBI!$A$4:$D$39,4,0))) | S52: =IF(A52="","",P52+G52)
G53: =IF(A53="","",E53/IF(A53=$B$3,Resumen!#REF!,VLOOKUP(A53,Graf_PowerBI!$A$4:$D$39,3,0))) | H53: =IF(A53="","",F53/IF(A53=$B$3,Resumen!#REF!,VLOOKUP(A53,Graf_PowerBI!$A$4:$D$39,4,0))) | P53: =IF(J53="","",N53/IF(J53=$B$3,Resumen!#REF!,VLOOKUP(J53,Graf_PowerBI!$A$4:$D$39,3,0))) | Q53: =IF(J53="","",O53/IF(J53=$B$3,Resumen!#REF!,VLOOKUP(J53,Graf_PowerBI!$A$4:$D$39,4,0))) | S53: =IF(A53="","",P53+G53)
G54: =IF(A54="","",E54/IF(A54=$B$3,Resumen!#REF!,VLOOKUP(A54,Graf_PowerBI!$A$4:$D$39,3,0))) | H54: =IF(A54="","",F54/IF(A54=$B$3,Resumen!#REF!,VLOOKUP(A54,Graf_PowerBI!$A$4:$D$39,4,0))) | P54: =IF(J54="","",N54/IF(J54=$B$3,Resumen!#REF!,VLOOKUP(J54,Graf_PowerBI!$A$4:$D$39,3,0))) | Q54: =IF(J54="","",O54/IF(J54=$B$3,Resumen!#REF!,VLOOKUP(J54,Graf_PowerBI!$A$4:$D$39,4,0))) | S54: =IF(A54="","",P54+G54)
G55: =IF(A55="","",E55/IF(A55=$B$3,Resumen!#REF!,VLOOKUP(A55,Graf_PowerBI!$A$4:$D$39,3,0))) | H55: =IF(A55="","",F55/IF(A55=$B$3,Resumen!#REF!,VLOOKUP(A55,Graf_PowerBI!$A$4:$D$39,4,0))) | P55: =IF(J55="","",N55/IF(J55=$B$3,Resumen!#REF!,VLOOKUP(J55,Graf_PowerBI!$A$4:$D$39,3,0))) | Q55: =IF(J55="","",O55/IF(J55=$B$3,Resumen!#REF!,VLOOKUP(J55,Graf_PowerBI!$A$4:$D$39,4,0))) | S55: =IF(A55="","",P55+G55)
... G253: =IF(A253="","",E253/IF(A253=$B$3,Resumen!#REF!,VLOOKUP(A253,Graf_PowerBI!$A$4:$D$39,3,0))) | H253: =IF(A253="","",F253/IF(A253=$B$3,Resumen!#REF!,VLOOKUP(A253,Graf_PowerBI!$A$4:$D$39,4,0))) | P253: =IF(J253="","",N253/IF(J253=$B$3,Resumen!#REF!,VLOOKUP(J253,Graf_PowerBI!$A$4:$D$39,3,0))) | Q253: =IF(J253="","",O253/IF(J253=$B$3,Resumen!#REF!,VLOOKUP(J253,Graf_PowerBI!$A$4:$D$39,4,0))) | S253: =IF(A253="","",P253+G253)

Sheet cuotas diario
B1: pase | I1: consumo a cuotas
B2: CODMES | C2: FECHA | D2: PONDERADO | E2: FACTU | F2: CLIENTES | I2: CODMES | J2: FECTRANSACCION | K2: CLIENTES | L2: PONDCUOTAS | M2: FACTUTOTAL
B3: 202301 | C3: 44927 | D3: 6.1854641 | E3: 0.76703633 | F3: 1.416 | I3: 202301 | J3: 44927 | K3: 1.55 | L3: 3.1055162 | M3: 0.54206019
B4: 202301 | C4: 44928 | D4: 14.58998 | E4: 1.8920803 | F4: 3.052 | I4: 202301 | J4: 44928 | K4: 6.308 | L4: 24.598104 | M4: 3.4881359
B5: 202301 | C5: 44929 | D5: 11.589479 | E5: 1.5372219 | F5: 2.446 | I5: 202301 | J5: 44929 | K5: 6.737 | L5: 26.932852 | M5: 3.602261
B6: 202301 | C6: 44930 | D6: 27.038417 | E6: 3.3006168 | F6: 5.407 | I6: 202301 | J6: 44930 | K6: 6.25 | L6: 28.227533 | M6: 3.5853843
B7: 202301 | C7: 44931 | D7: 27.767183 | E7: 3.1470803 | F7: 4.714 | I7: 202301 | J7: 44931 | K7: 6.643 | L7: 28.60398 | M7: 3.8312494
B8: 202301 | C8: 44932 | D8: 21.417934 | E8: 2.603463 | F8: 3.802 | I8: 202301 | J8: 44932 | K8: 6.395 | L8: 29.630912 | M8: 3.5662649
B9: 202301 | C9: 44933 | D9: 13.752548 | E9: 1.6265303 | F9: 2.49 | I9: 202301 | J9: 44933 | K9: 7.169 | L9: 26.939494 | M9: 3.6891741
B10: 202301 | C10: 44934 | D10: 8.4692876 | E10: 1.1466035 | F10: 1.687 | I10: 202301 | J10: 44934 | K10: 5.814 | L10: 20.800428 | M10: 2.6852187
B11: 202301 | C11: 44935 | D11: 15.836533 | E11: 1.8535061 | F11: 2.602 | I11: 202301 | J11: 44935 | K11: 6.802 | L11: 33.434137 | M11: 4.0693647
B12: 202301 | C12: 44936 | D12: 27.648181 | E12: 3.1127899 | F12: 4.551 | I12: 202301 | J12: 44936 | K12: 6.635 | L12: 27.043692 | M12: 3.71601
B13: 202301 | C13: 44937 | D13: 21.73302 | E13: 2.5520683 | F13: 3.753 | I13: 202301 | J13: 44937 | K13: 6.729 | L13: 36.066127 | M13: 3.9656071
B14: 202301 | C14: 44938 | D14: 16.719166 | E14: 1.837196 | F14: 2.733 | I14: 202301 | J14: 44938 | K14: 6.54 | L14: 32.453569 | M14: 3.8631775
B15: 202301 | C15: 44939 | D15: 12.327119 | E15: 1.552252 | F15: 2.583 | I15: 202301 | J15: 44939 | K15: 6.314 | L15: 26.376414 | M15: 3.4872926
B18: 202301 | C18: 44940 | D18: 10.61894 | E18: 1.2712743 | F18: 2.067
B19: 202301 | C19: 44941 | D19: 8.2438488 | E19: 0.93700833 | F19: 1.726
B20: 202301 | C20: 44942 | D20: 10.953374 | E20: 1.5161362 | F20: 2.423
B21: 202301 | C21: 44943 | D21: 25.493636 | E21: 2.6062979 | F21: 4.178
B22: 202301 | C22: 44944 | D22: 0.05356689 | E22: 0.00704906 | F22: 0.015
B25: CODMES | C25: FECHA | D25: PONDERADO | E25: FACTU | F25: CLIENTES | I25: CODMES | J25: FECTRANSACCION | K25: CLIENTES | L25: PONDCUOTAS | M25: FACTUTOTAL
B26: 202301 | C26: 44927 | D26: 6.1854641 | E26: 0.76703633 | F26: 1.416 | I26: 202301 | J26: 44927 | K26: 1.55 | L26: 3.1055162 | M26: 0.54206019
B27: 202301 | C27: 44928 | D27: 14.58998 | E27: 1.8920803 | F27: 3.052 | I27: 202301 | J27: 44928 | K27: 6.308 | L27: 24.598104 | M27: 3.4881359
B28: 202301 | C28: 44929 | D28: 11.589479 | E28: 1.5372219 | F28: 2.446 | I28: 202301 | J28: 44929 | K28: 6.738 | L28: 26.932894 | M28: 3.602282
B29: 202301 | C29: 44930 | D29: 27.038417 | E29: 3.3006168 | F29: 5.407 | I29: 202301 | J29: 44930 | K29: 6.25 | L29: 28.227533 | M29: 3.5853843
B30: 202301 | C30: 44931 | D30: 27.767183 | E30: 3.1470803 | F30: 4.714 | I30: 202301 | J30: 44931 | K30: 6.643 | L30: 28.60398 | M30: 3.8312494
B31: 202301 | C31: 44932 | D31: 21.417934 | E31: 2.603463 | F31: 3.802 | I31: 202301 | J31: 44932 | K31: 6.396 | L31: 29.631152 | M31: 3.5663849
B32: 202301 | C32: 44933 | D32: 13.752548 | E32: 1.6265303 | F32: 2.49 | I32: 202301 | J32: 44933 | K32: 7.169 | L32: 26.939494 | M32: 3.6891741
B33: 202301 | C33: 44934 | D33: 8.4692876 | E33: 1.1466035 | F33: 1.687 | I33: 202301 | J33: 44934 | K33: 5.814 | L33: 20.801028 | M33: 2.6853687
B34: 202301 | C34: 44935 | D34: 15.836533 | E34: 1.8535061 | F34: 2.602 | I34: 202301 | J34: 44935 | K34: 6.806 | L34: 33.479357 | M34: 4.0749329
B35: 202301 | C35: 44936 | D35: 27.648181 | E35: 3.1127899 | F35: 4.551 | I35: 202301 | J35: 44936 | K35: 6.639 | L35: 27.052035 | M35: 3.7186669
B36: 202301 | C36: 44937 | D36: 21.73302 | E36: 2.5520683 | F36: 3.753 | I36: 202301 | J36: 44937 | K36: 6.73 | L36: 36.079815 | M36: 3.9690293
B37: 202301 | C37: 44938 | D37: 16.719166 | E37: 1.837196 | F37: 2.733 | I37: 202301 | J37: 44938 | K37: 6.55 | L37: 32.922493 | M37: 3.9052403
... B45: 202301 | C45: 44946 | D45: 15.968885 | E45: 2.0052134 | F45: 3.105 | I45: 202301 | J45: 44946 | K45: 6.411 | L45: 24.309333 | M45: 3.3131981
B46: 202301 | C46: 44947 | D46: 8.8128016 | E46: 1.0475035 | F46: 2.088
B47: 202301 | C47: 44948 | D47: 6.7917639 | E47: 0.81391181 | F47: 1.398
B48: 202301 | C48: 44949 | D48: 8.4667582 | E48: 1.1554155 | F48: 2.066
B49: 202301 | C49: 44950 | D49: 19.566885 | E49: 2.225844 | F49: 3.892
B50: 202301 | C50: 44951 | D50: 14.322174 | E50: 1.6034034 | F50: 2.741
B51: 202301 | C51: 44952 | D51: 0.0156124 | E51: 0.0025673 | F51: 0.004
...

Sheet AMEX
A1: TOTAL | Q1: Proyección Crecimiento Amex
A3: AMEX | B3: 202009 | C3: 202010 | D3: 202011 | E3: 202012 | F3: 202101 | G3: 202102 | H3: 202103 | I3: 202104 | J3: 202105 | K3: 202106 | L3: 202107 | M3: 202108 | N3: 202109 | O3: Proyec Set | Q3: 202103 | R3: 202104 | S3: 202105 | T3: 202106 | U3: 202107 | V3: 202108 | W3: 202109 | X3: 202110 | Y3: 202111 | Z3: 202112
A4: Facturación
A5: Real | B5: 1.4109552e+08 | C5: 1.5463585e+08 | D5: 1.6011516e+08 | E5: 1.89275e+08 | F5: 1.6749357e+08 | G5: 1.4008782e+08 | H5: 1.9790088e+08 | I5: 1.8689541e+08 | J5: 2.1633951e+08 | K5: 2.1387149e+08 | L5: 2.4496765e+08 | M5: 2.4800996e+08 | N5: =Resumen!#REF!*1000000 -> #REF! | O5: =Resumen!B5*Resumen!#REF!*1000000 -> #REF! | P5: =O5/R5 -> #REF! | Q5: 162569329 | R5: 157859429 | S5: 1.7234807e+08 | T5: 1.6544786e+08 | U5: 1.8250957e+08 | V5: 1.7440558e+08 | W5: 1.7158987e+08 | X5: 1.8768119e+08 | Y5: 1.9587551e+08 | Z5: 2.1556457e+08
A6: PPTO | B6: 141219000 | C6: 153477858 | D6: 157524919 | E6: 169377536 | F6: 1.486702e+08 | G6: 1.4630181e+08 | H6: 1.6146462e+08 | I6: 1.5531378e+08 | J6: 1.6717039e+08 | K6: 1.5880528e+08 | L6: 1.749082e+08 | M6: 1.6691863e+08 | N6: 1.6349374e+08
A7: Cumpl | B7: =B5/B6 -> 0.99912562 | C7: =C5/C6 -> 1.007545 | D7: =D5/D6 -> 1.0164434 | E7: =E5/E6 -> 1.117474 | F7: =F5/F6 -> 1.1266116 | G7: =G5/G6 -> 0.95752618 | H7: =H5/H6 -> 1.225661 | I7: =I5/I6 -> 1.2033409 | ... N7: =N5/N6 -> #REF! | O7: =O5/N6 -> #REF!
A8: %Share marca | B8: =+B5/(B5+B29) -> 0.269854 | C8: =+C5/(C5+C29) -> 0.26838626 | D8: =+D5/(D5+D29) -> 0.26677905 | E8: =+E5/(E5+E29) -> 0.26684064 | F8: =+F5/(F5+F29) -> 0.26608771 | G8: =+G5/(G5+G29) -> 0.26092506 | H8: =+H5/(H5+H29) -> 0.26439563 | I8: =+I5/(I5+I29) -> 0.26442489 | ... O8: =+O5/(O5+O29) -> #REF! | Q8: =+Q5/(Q5+Q29) -> 0.26630915 | R8: =+R5/(R5+R29) -> 0.27019945 | S8: =+S5/(S5+S29) -> 0.276947
A10: Entregas | B10: 1871 | C10: 2024 | D10: 1940 | E10: 3484 | F10: 3919 | G10: 3601 | H10: 3922 | I10: 3425 | J10: 4652 | K10: 3815 | L10: 4037 | M10: 5429 | N10: 1112 | O10: =+(Resumen!#REF!*1000)*(N10/(N10+N34)) -> #REF! | P10: =O10/Q10 -> #REF! | Q10: 3657.348 | R10: 3547.9293 | S10: 3778.0617 | T10: 3789.6221 | U10: 3948.7367 | V10: 4113.4502 | W10: 4199.8867 | X10: 4195.6764 | Y10: 4215.3576 | Z10: 4133.9613
F11: =+F10/(F10+F34) -> 0.23004226 | G11: =+G10/(G10+G34) -> 0.23811413 | H11: =+H10/(H10+H34) -> 0.20971019 | I11: =+I10/(I10+I34) -> 0.18939394 | J11: =+J10/(J10+J34) -> 0.18827148 | K11: =+K10/(K10+K34) -> 0.18016529 | L11: =+L10/(L10+L34) -> 0.19211002 | M11: =+M10/(M10+M34) -> 0.20622982 | N11: =+N10/(N10+N34) -> 0.20619321 | Q11: =+Q10/(Q10+Q34) -> 0.20643921 | R11: =+R10/(R10+R34) -> 0.20746739 | S11: =+S10/(S10+S34) -> 0.20830894 | T11: =+T10/(T10+T34) -> 0.20925511 | U11: =+U10/(U10+U34) -> 0.20737247 | V11: =+V10/(V10+V34) -> 0.20867459 | W11: =+W10/(W10+W34) -> 0.20806175 | X11: =+X10/(X10+X34) -> 0.2093291 | ... Z11: =+Z10/(Z10+Z34) -> 0.21123713
A12: Parque | B12: 210260 | C12: 208479 | D12: 206415 | E12: 204649 | F12: 202429 | G12: 201888 | H12: 201788 | I12: 197271 | J12: 198006 | K12: 197653 | L12: 197274 | M12: 200190 | O12: =+(Resumen!B33*1000)*(M12/(M12+M36)) -> 204534.68 | P12: =O12/Q12 -> 1.0162859 | Q12: 201257.02 | R12: 203873.64 | S12: 206744.49 | T12: 208595.87 | U12: 209032.99 | V12: 209858.45 | W12: 210994.17 | X12: 212335.47 | Y12: 213754.99 | Z12: 215368.54
F13: =+F12/(F12+F36) -> 0.23392515 | G13: =+G12/(G12+G36) -> 0.23397566 | H13: =+H12/(H12+H36) -> 0.2331335 | I13: =+I12/(I12+I36) -> 0.23638603 | J13: =+J12/(J12+J36) -> 0.2351713 | K13: =+K12/(K12+K36) -> 0.23479945 | L13: =+L12/(L12+L36) -> 0.2337558 | M13: =+M12/(M12+M36) -> 0.23270899 | ... O13: =+O12/(O12+O36) -> 0.23270899 | Q13: =+Q12/(Q12+Q36) -> 0.23466144 | R13: =+R12/(R12+R36) -> 0.23910383 | S13: =+S12/(S12+S36) -> 0.24347768 | T13: =+T12/(T12+T36) -> 0.24817219 | U13: =+U12/(U12+U36) -> 0.24841723 | V13: =+V12/(V12+V36) -> 0.24861161 | W13: =+W12/(W12+W36) -> 0.24873293 | X13: =+X12/(X12+X36) -> 0.24887036 | ... Z13: =+Z12/(Z12+Z36) -> 0.24918497
A15: Bloq+Canc-Desb | C15: 3652 | D15: 4088 | E15: 3706 | F15: 5704 | G15: 4142 | H15: =+G12+H10-H12 -> 4022 | I15: =+H12+I10-I12 -> 7942 | J15: =+I12+J10-J12 -> 3917 | K15: =+J12+K10-K12 -> 4168 | L15: =+K12+L10-L12 -> 4416 | M15: =+L12+M10-M12 -> 2513 | N15: =+M12+N10-N12 -> 201302 | O15: =+G12+O10-O12 -> #REF! | P15: =O15/Q15 -> #REF! | Q15: 4288.3263 | R15: 4292.2944 | S15: 4268.1872 | T15: 5299.2322 | U15: 3511.6101 | V15: 3287.9956 | W15: 3064.1659 | X15: 2854.3744 | Y15: 2795.8328 | Z15: 2520.4156
A16: Bloqueos | B16: 3511 | C16: 4076 | D16: 3249 | E16: 2966 | F16: 2634 | G16: 2454 | H16: 2333 | I16: 1851 | J16: 2515 | K16: 1825 | L16: 2852 | M16: 1965
C17: =+C16/B12 -> 0.019385523 | D17: =+D16/C12 -> 0.015584303 | E17: =+E16/D12 -> 0.014369111 | F17: =+F16/E12 -> 0.012870818 | G17: =+G16/F12 -> 0.012122769 | H17: =+H16/G12 -> 0.011555912 | I17: =+I16/H12 -> 0.0091729934 | J17: =+J16/I12 -> 0.01274896 | ... N17: =+N16/M12 -> 0
